Workbook

Sheet Informe Semanal
D3: Reporte Semanal de Proyectos | P3: Fecha corte: | Q3: 46128
G4: 477-PRI24045-000-083-RS-0054 | P4: Emitido : | Q4: =+Q3+1 -> 46129
B6: Proyecto: | C6: EIA Proyecto ACP - Contrato PRI24045 “Ampliación Capacidad Productiva Collahuasi”
B8: Apreciación Gerencial del Proyecto Semanal | J8: Hechos Relevantes de la Semana y Próxima Semana | S8: =900*0.07 -> 63
S15: 
S16: 
B18: Alertas y Oportunidades | S18: 
B19: Área | D19: Alertas | H19: Impacto | L19: Plan de Acción | O19: Responsable | Q19: Plan | R19: Forecast | S19: 
B20: Medio Ambiente y Permisos | C20: 0 | D20: En función de la nueva "Guía para la predicción y evaluación de impactos sobre ecosistemas terrestres" (agosto, 2025), se requiere incorporar mediciones de MPS en el sector cordillera, ductos alto (por Metharme lanata y vegetación azonal) y sector pampa tamarugal. | H20: Posible cuestionamiento de la evaluación de impactos del Proyecto, por falta de antecedentes de línea de base. | L20: 1.- WSP enviará un presupuesto de instalación de MPS de la empresa EMS. 2.-Solicitar a Teck la obtención de datos de MPS. 3.- Instalación de estaciones de monitoreo de MPS en los sectores de las áreas sensibles de flora y vegetación identificadas a través de la línea de base ejecutada. | O20: 1.- WSP 2.- Collahuasi 3.- WSP /Collahuasi | Q20: 1.- mar-2026 2.- abr-2026 3.- dic-2025 4.- jun-2026 | R20: 1.-abr-2026 2.- abr-2026 3.- jun-2026
C21: 0 | D21: Geología, Geomorfología y Riesgo Geológico: Información insuficiente para la elaboración de la línea de base de Geología, Geomorfología y Riesgos Geológicos. | H21: Cuestionamientos por parte de la Autoridad en proceso de tramitación del Proyecto. | L21: 1.- WSP envió la Propuesta técnica y económica sobre las brechas de información para la ldb de GGR (03/02). 2.- Se espera la revisión y definición de la propuesta técnica y económica compartida por WSP. | O21: 1.- WSP 2.- Collahuasi | Q21: 1.- 03-feb-2026 2.- feb-2026 | R21: 1.- 03-feb-2026 2.- abr-2026
C22: 2 | D22: Campaña de áreas pendientes y adicionales de Arqueología: Se necesita definir la fecha de ejecución de la campaña de arqueología para las áreas pendientes y adicionales. | H22: Potencial requerimiento de elaboración, tramitación y ejecución de un FSA 4, lo que podría impactar en el Programa del servicio. | L22: 1.- WSP debe enviar Plan de Trabajo sobre áreas pendientes, una vez contemos con la actualización del Layout del Proyecto, se estima que esta campaña se retomará posterior a la las campañas de pozos de sondeo. | O22: 1.- WSP 2.- WSP | Q22: 1.- 20-mar-2026 2.- 17-abr-2026
C23: -1 | D23: Levantamiento de información para elaborar DIN y PAS 150 | H23: Ejecutar un método para definir y delimitar el BNP cuestionado en etapas de evaluación ambiental | L23: 1.- A la espera de comentarios por parte de Collahuasi sobre el ppt enviada el día viernes 10/04. 2.- Collahuasi debe gestionar reunión con CONAF (vía Lobby) programada para segunda quincena de abril. El objetivo es validar la metodología para la delimitación del BNP. | O23: 1. Collahuasi 2. Collahuasi | Q23: 1.- 22-abr-2026 2.- 13-05-2026
C24: 0 | D24: Atraso de la ejecución de las campañas de Medio Humano y Participación Ciudadana Temprana | H24: Atraso en el avance del Proyecto, que podría pegar en la fecha de ingreso del EIA, ya que corresponden a actividades que se encuentran en la ruta crítica, además involucra el atraso en la elaboración de líneas de base como: - Atractivos Naturales o culturales y sus interacciones | L24: 1.- Se encuentra en proceso de validación la reprogramación del EIA (R2), no obstante, el componente se mantiene en ruta crítica. 2.- Se requiere habilitación por parte de Collahuasi previo a la ejecución de los terrenos. | O24: 1.- Collahuasi 2.- WSP | Q24: 1.- abril-2026 2.- De acuerdo a programa R2
C25: 2 | D25: Seguimiento de los compromisos establecidos durante el proceso de ejecución de los Hitos 4, 8, 9 y 10 | H25: Falta de información relevante para el desarrollo del EIA, debido a ausencia de seguimiento de acciones requeridas para aspectos críticos del proyecto | L25: 1.- Agendar reuniones de seguimiento por componente para revisar el desarrollo del compromiso y fechas de implementación. 2.- Identificar las acciones requeridas en el corto plazo (Abril - Mayo) y enviar correo a Collahuasi. | O25: WSP | Q25: 46101 | R25: 46113
B29: Indicadores de Planificación (Programa del Servicio R1) | F29: Curva "S" del Proyecto
B31: % Av. Real | C31: % Av. Prog. | D31: M
B32: ACUMULADO
B33: =+EPR!L7 -> 0.4473832 | C33: =+'Curva S R1'!BE34/100 -> 0.49978764 | D33: =+B33-C33 -> -0.052404438 | E33: 0
B34: PARCIAL
B35: =+'Curva S R1'!BE35/100 -> 0.0043510811 | C35: =+'Curva S R1'!BE33/100 -> 0.016323917 | D35: =+B35-C35 -> -0.011972836
B37: HH Proyecto | C37: Ganadas | D37: Planificadas | E37: SPI
B38: Semanal | C38: =+'Curva S R1'!BE61 -> 545.73 | D38: =+'Curva S R1'!BE55 -> 2047.4 | E38: =+C38/D38 -> 0.26654782
B39: Acumulado | C39: =+'Curva S R1'!BE62 -> 50288.4 | D39: =+'Curva S R1'!BE56 -> 62685.03 | E39: =+C39/D39 -> 0.80223939
B41: Hitos Relevantes (Incluidos Contractuales)
G53: Motivo Desviación: 1.- Actividades de Gestión del Proyecto (-0,6%): Hasta la fecha se han realizado 17 reuniones técnicas, lo que representa un avance del 23,6% en esta actividad, considerando que el total programado es de 72 reuniones a ejecutarse hasta diciembre de 2026 y llevamos 45 reuniones contractuales, lo que representa un 36% de avance, de un total de 125 reuniones programadas. 2.- Cap. 10 - Plan de cumplimiento de la legislación ambiental aplicable y PAS 119 Pesca investig. Aguas Marinas (-0,1%): La fecha de elaboración de estos documentos fue actualizada en el programa R2 preliminar 3.- Estudio de Olores - (-0,2%): Inicio pendiente a la espera del proyecto definitivo. 4.- Estudios Específicos - levantamiento en terreno solicitud excepcional cuenca 1 y 2, Definición sitios de compensación y/o relocalización (-1,5%): Actividad proyectada para ser ejecutada con posterioridad. 5.- Clima y Meteorología / Calidad del Aire (-0,6%): Atraso en el desarrollo de informes (RA), por falta de antecedentes necesarios para el inicio del documento. 6.- Suelos (-0,1%): Trabajos de terreno iniciará el 21/abr/26. 7.- Animales Silvestres (0,1%): Elaboración y envío de informes sobre campañas estacionales bióticas. 8.- Paisaje (-0,2%): Segunda parte de la campaña ejecutada, inicia elaboración de informe. 9.- Atractivos Naturales o Culturales y sus Interrelaciones (Turismo) (-0,4%): Campaña detenida ya que requiere interacción con operadores turísticos que potencialmente podrían ser parte de alguna comunidad, por lo que se encuentra sujeta a la activación de la campaña de Medio Humano. 10.- Geología, Geomorfología, Riesgos Geológicos y Geomorfológicos (-0,1%): Esta actividad se atrasó en su inicio debido a la falta de información para su elaboración. Se encuentra en desarrollo. 11.- Arqueología (-1,0%): Está pendiente trabajos de terreno arqueología (campaña prospecciones - 3) y el inicio de la ejecución de pozos de sondeo. 12.- Ecosistemas Acuáticos Marinos - Informe (RB) - Recursos hídricos marinos (campaña invierno y verano) (-0,3%): Informe de campañas en desarrollo. 13.- Medio Humano - Estudio Antropológico (por GHPPI) (-2,0%): Los trabajos de Medio Humano se encuentran suspendidos hasta contar con un relato que integre la DIA 3 y el EIA ACP. 14.- Medio Humano - Grupos Humanos no Indígenas (-1,3%): Los trabajos de Medio Humano se encuentran suspendidos hasta contar con un relato que integre la DIA 3 y el EIA ACP. 15.- Caracterización Vial (-0,4%): Terreno detenido por definición de proyecto definitivo 16.- Proceso de Consulta Temprana (PCT) (-1,2%): Esta actividad se encuentra pendiente de reprogramación, sin embargo, se dio inicio a la elaboración de la Estrategia. 17.- Tendencia 5 - Esfuerzos de Terreno Adicional (Aspectos Bióticos), Campaña 2025 / Tendencia 6 - Trazado Alternativo LTE / Tendencia 8 - Control Operacional en Terreno / Tendencia 9 - Brigada Canina / Tendencia 10 Campaña de Verano Área de Estudio / Tendencia N°12 - Campaña Biótica Complementaria Otoño (4,7%): Se incluye tendencias con HH ganadas de tareas ejecutadas a la fecha.
B56: Indicadores de Costos | I56: Tendencias
I65: 1.- Tendencia N°11: Estudio de Capacidad de Carga - Rechazado por CMDIC (01/abr). Se emite TD11 R1 el 10/abr (TRN-000191). En actualización para clarificar cantidad de entregables. Se envía corregida el 16/abr/26. 2.- Tendencia N°12: Campaña Adicional de Otoño - Aprobada el 14/abr/26. 3.- Orden de Cambio N°1: Firmada por representantes legales de WSP en el portal “CloudSigner”. 4.- Tendencia administrativa: Se envió borrador de Tendencia por extensión del servicio el 09/abr/26. 5.- Tendencia 13: Ruta A97B (Biota y Arqueología + Áreas Adicionales Arqueología), emitida el 16/abr/26. 6.- Se incluyen Tendencias Potenciales en el Log de Tendencias con valores aproximados. 7.- Emisión tendencia estaciones MPS
B71: Resumen Entregables
G72: Comentarios:
S81:  | T81: Entrega Estudio Antropológicos, incluyendo fuentes primarias:
B82: (*) Se actualiza cantidad de entregables de acuerdo a nueva línea de base | P82: FIRMA | S82: o | T82: GHPPI Segovia-Jauregui (WSP).
S83: o | T83: GHPPI Familia Vicentelo de Tamentica (WSP).
S84:  | T84: Avance fuentes secundarias línea base medio humano.
S85: o | T85: Recorrido GHPPI Chusquina-Huari Plaza (GEO).
T86: Avance fuentes secundarias línea base medio humano.

Sheet EPR
K3: Ppto HH | L3: % Avance | N3: HH Ganadas
H4: Contrato Original | K4: =SUM(K11:K659)-27 -> 117644.55 | L4: =+N4/K4 -> 0.36773751 | N4: =SUM(N11:N659) -> 43262.313 | Q4: Data Date | R4: =+'Informe Semanal'!$Q$3 -> 46128
H5: Contrato + Tend | K5: =+K660+L724 -> 125408.55 | L5: =+N5/K5 -> 0.40100881 | N5: =+N660+N724 -> 50289.933
H6: PROGRAMA_R1 | K6: =+K5+15 -> 125423.55 | L6: =+N6/K6 -> 0.40096085 | N6: =+N5 -> 50289.933 | R6: 0.4 | S6: 0.2 | T6: 0.1 | U6: 0.2 | V6: 0.1 | X6: 0.4 | Y6: 0.2 | Z6: 0.1 | AA6: 0 | AB6: 0 | AC6: 0.2 | AD6: 0.1 | AF6: 0.4 | AG6: 0.2 | AH6: 0.1 | AI6: 0.2 | AJ6: 0.1
H7: PR1+TD5+6+8+9+10+12 | K7: =+K6+M871 -> 146397.95 | L7: =+N7/K7 -> 0.4473832 | N7: =+N6+N871 -> 65495.983
H9: Tipo Entregable | Q9: PLANIFICADO PROGRAMA REV_1 | W9: REAL | AE9: FORECAST
B10: ITEM | C10: Origen Programa P6 (Activity ID) Rev.0 | D10: Status (Rev.0) | E10: Cód. CMDIC | F10: DESCRIPCIÓN | G10: DISCIPLINA | H10: DOC | I10: PLA | J10: ACT | K10: HH CO | L10: HH TD | M10: HH Total Ppto | N10: HH Total Ganadas | O10: % Avance Programado | P10: % Avance Real | Q10: Inicio | R10: Emisión RevA | S10: Emisión RevB | T10: Aprobación RevB | U10: Emisión RevP | V10: Aprobación RevP (Término Actividades) | W10: Inicio | X10: Emisión RevA | Y10: Emisión RevB | Z10: Aprobación RevB | AA10: Emisión RevC | AB10: Aprobación RevC | AC10: Emisión RevP | AD10: Aprobación RevP (Término Actividades) | AE10: Inicio | AF10: Emisión RevA | AG10: Emisión RevB | AH10: Aprobación RevB | AI10: Emisión RevP | AJ10: Aprobación RevP (Término Actividades) | AK10: 44620 | AL10: =+AK10+7 -> 44627 | AM10: =+AL10+7 -> 44634 | AN10: =+AM10+7 -> 44641 | AO10: =+AN10+7 -> 44648 | AP10: =+AO10+7 -> 44655 | AQ10: =+AP10+7 -> 44662 | AR10: =+AQ10+7 -> 44669 | AS10: =+AR10+7 -> 44676 | ... CP10: =+CO10+7 -> 45019
B11: 1 | F11: GENERAL (Activ. de Coodinación y Supervisión)
B12: 1.1 | F12: ACTIVIDADES | M12: =+K12+L12 -> 0 | N12: =+M12*P12 -> 0
A13: =+TRIM(C13) -> 477-010-40-0001 | B13: 1.1.1 | C13: 477-010-40-0001 | D13: Semanal (35 de 49) | E13: 477-PRI24045-000-010-ME-1001 a 1049 | F13: Reunión Ejecutiva | J13: 1 | K13: 294 | M13: =+K13+L13 -> 294 | N13: =+M13*P13 -> 210 | O13: =IFERROR(VLOOKUP(C13,'Programa P6 Excel R1'!$B$4:$N$1142,8,FALSE),"-") -> 0.646 | P13: =35/49 -> 0.71428571 | Q13: 45827 | V13: 46295 | W13: 45817 | AJ13: 46295
A14: =+TRIM(C14) -> 477-010-40-0002 | B14: 1.1.2 | C14: 477-010-40-0002 | D14: Semanal (45 de 125) | E14: 477-PRI24045-000-035-ME-0001 a 0125 | F14: Reunión Contractual Semanal | J14: 1 | K14: 1000 | M14: =+K14+L14 -> 1000 | N14: =+M14*P14 -> 360 | O14: =IFERROR(VLOOKUP(C14,'Programa P6 Excel R1'!$B$4:$N$1142,8,FALSE),"-") -> 0.4185 | P14: =45/125 -> 0.36 | Q14: 45751 | V14: 46659 | W14: 45819 | AJ14: 46659
A15: =+TRIM(C15) -> 477-010-40-0003 | B15: 1.1.3 | C15: 477-010-40-0003 | D15: Semanal (17 de 72) | E15: 477-PRI24045-000-010-ME-2001 a 2072 | F15: Reunión Técnica | J15: 1 | K15: 1383.84 | M15: =+K15+L15 -> 1383.84 | N15: =+M15*P15 -> 326.74 | O15: =IFERROR(VLOOKUP(C15,'Programa P6 Excel R1'!$B$4:$N$1142,8,FALSE),"-") -> 0.5968 | P15: =17/72 -> 0.23611111 | Q15: 45751 | V15: 46387 | W15: 45819 | AJ15: 46387
A16: =+TRIM(C16) -> 477-010-40-0004 | B16: 1.1.4 | C16: 477-010-40-0004 | E16: 477-PRI24045-000-010-ME-3001 a 3020 | F16: Reuniones con autoridades | J16: 1 | K16: 490 | M16: =+K16+L16 -> 490 | N16: =+M16*P16 -> 0 | O16: =IFERROR(VLOOKUP(C16,'Programa P6 Excel R1'!$B$4:$N$1142,8,FALSE),"-") -> 0.2533 | P16: 0 | Q16: 46048 | V16: 46378 | AE16: 46048 | AJ16: 46378
A17: =+TRIM(C17) -> 477-010-40-0005 | B17: 1.1.5 | C17: 477-010-40-0005 | D17: Semanal (54 de 125) | E17: 477-PRI24045-000-083-RS-0001 a 0125 | F17: Reportes Semanales | H17: 1 | K17: 2125 | M17: =+K17+L17 -> 2125 | N17: =+M17*P17 -> 918 | O17: =IFERROR(VLOOKUP(C17,'Programa P6 Excel R1'!$B$4:$N$1142,8,FALSE),"-") -> 0.4072 | P17: =54/125 -> 0.432 | Q17: 45769 | V17: 46659 | W17: 45821 | AJ17: 46659
B18: 1.1.6 | F18: Programa de Ejecución del Servicio | O18: =IFERROR(VLOOKUP(C18,'Programa P6 Excel R1'!$B$4:$N$1142,8,FALSE),"-") -> - | Q18: - | V18: - | AE18: - | AJ18: -
A19: =+TRIM(C19) -> 477-010-40-0006 | B19: 1.1.7 | C19: 477-010-40-0006 | D19: Rev.0 | E19: 477-PRI24045-000-083-PG-0001 | F19: Programa de Ejecución del Servicio | H19: 1 | K19: 303 | M19: =+K19+L19 -> 303 | N19: =+M19*P19 -> 303 | O19: =IFERROR(VLOOKUP(C19,'Programa P6 Excel R1'!$B$4:$N$1142,8,FALSE),"-") -> 1 | P19: 1 | Q19: 45751 | V19: 45819 | W19: 45751 | X19: 45771 | Y19: 45771 | Z19: - | AA19: 45793 | AB19: 45803 | AC19: 45820 | AD19: 45820
A20: =+TRIM(C20) -> 477-010-40-0007 | B20: 1.1.8 | C20: 477-010-40-0007 | D20: En desarrollo | F20: Control de Documentos | J20: 1 | K20: 1425 | M20: =+K20+L20 -> 1425 | N20: =+M20*P20 -> 842.46 | O20: =IFERROR(VLOOKUP(C20,'Programa P6 Excel R1'!$B$4:$N$1142,8,FALSE),"-") -> 0.5912 | P20: =+'Programa P6 Excel R1'!J39 -> 0.5912 | Q20: 45761 | V20: 46387 | W20: 45751 | AE20: 45761 | AJ20: 46387
B21: 1.1.9 | F21: Acreditación | O21: =IFERROR(VLOOKUP(C21,'Programa P6 Excel R1'!$B$4:$N$1142,8,FALSE),"-") -> - | Q21: - | V21: - | AE21: - | AJ21: -
A22: =+TRIM(C22) -> 477-010-40-0008 | B22: 1.1.10 | C22: 477-010-40-0008 | D22: En desarrollo | F22: Carpeta de arranque | J22: 1 | K22: 270 | M22: =+K22+L22 -> 270 | N22: =+M22*P22 -> 249.075 | O22: =IFERROR(VLOOKUP(C22,'Programa P6 Excel R1'!$B$4:$N$1142,8,FALSE),"-") -> 0.9225 | P22: =+'Programa P6 Excel R1'!J40 -> 0.9225 | Q22: 45751 | V22: 46161 | W22: 45754 | AJ22: 46161
A23: =+TRIM(C23) -> 477-010-40-0009 | B23: 1.1.11 | C23: 477-010-40-0009 | D23: En desarrollo | F23: Carpeta de arranque SC | J23: 1 | K23: 415 | M23: =+K23+L23 -> 415 | N23: =+M23*P23 -> 382.8375 | O23: =IFERROR(VLOOKUP(C23,'Programa P6 Excel R1'!$B$4:$N$1142,8,FALSE),"-") -> 0.9225 | P23: =+P22 -> 0.9225 | Q23: 45751 | V23: 46161 | W23: 45754 | AJ23: 46161
A24: =+TRIM(C24) -> 477-010-40-0010 | B24: 1.1.12 | C24: 477-010-40-0010 | D24: En desarrollo | F24: Acreditación de personas | J24: 1 | K24: 1527 | M24: =+K24+L24 -> 1527 | N24: =+M24*P24 -> 1408.6575 | O24: =IFERROR(VLOOKUP(C24,'Programa P6 Excel R1'!$B$4:$N$1142,8,FALSE),"-") -> 0.9225 | P24: =+P23 -> 0.9225 | Q24: 45751 | V24: 46161 | W24: 45754 | AJ24: 46161
A25: =+TRIM(C25) -> 477-010-40-0011 | B25: 1.1.13 | C25: 477-010-40-0011 | D25: En desarrollo | F25: Acreditación vehículos | J25: 1 | K25: 782 | M25: =+K25+L25 -> 782 | N25: =+M25*P25 -> 721.395 | O25: =IFERROR(VLOOKUP(C25,'Programa P6 Excel R1'!$B$4:$N$1142,8,FALSE),"-") -> 0.9225 | P25: =+P24 -> 0.9225 | Q25: 45751 | V25: 46161 | W25: 45754 | AJ25: 46161
A26: =+TRIM(C26) -> 477-010-40-0012 | B26: 1.1.14 | C26: 477-010-40-0012 | D26: Rev.P1 (emitido) | E26: 477-PRI24045-000-010-EL-0001 | F26: Listado de Entregables | H26: 1 | K26: 60 | M26: =+K26+L26 -> 60 | N26: =+M26*P26 -> 60 | O26: =IFERROR(VLOOKUP(C26,'Programa P6 Excel R1'!$B$4:$N$1142,8,FALSE),"-") -> 1 | P26: 1 | Q26: 45751 | V26: 45814 | W26: 45751 | X26: 45758 | Y26: 45758 | Z26: 45769 | AA26: - | AB26: - | AC26: P 30-04-2025 P1 06/06/25 | AD26: 45821
A27: =+TRIM(C27) -> 477-010-40-0013 | B27: 1.1.15 | C27: 477-010-40-0013 | E27: 477-PRI24045-000-010-ME-4001 a 4010 | F27: Talleres (accionistas, CMDIC y GMAP) | J27: 1 | K27: 1280 | M27: =+K27+L27 -> 1280 | N27: =+M27*P27 -> 0 | O27: =+'Programa P6 Excel R1'!I45 -> 0.1 | P27: 0 | Q27: 46120 | V27: 46126 | AE27: 46120 | AJ27: 46126
A28: =+TRIM(C28) -> 477-010-40-0014 | B28: 1.1.16 | C28: 477-010-40-0014 | E28: 477-PRI24045-000-010-ME-5001 a 5010 | F28: Talleres de definición estratégicas | J28: 1 | K28: 1230 | M28: =+K28+L28 -> 1230 | N28: =+M28*P28 -> 0 | O28: =+'Programa P6 Excel R1'!I56 -> 0 | P28: 0 | Q28: 46134 | V28: 46140 | AE28: 46134 | AJ28: 46140
M29: =+K29+L29 -> 0 | N29: =+M29*P29 -> 0
B30: 2 | F30: Elaboración EIA | M30: =+K30+L30 -> 0 | N30: =+M30*P30 -> 0
A31: =+TRIM(C31) -> 477-010-40-0019 | B31: 2.1 | C31: 477-010-40-0019 | D31: Rev.P (Aprobado) | E31: 477-PRI24045-001-010-IN-0001 | F31: Definición de los aspectos críticos del Proyecto y estrategia para abordarlos | H31: 1 | K31: 832 | M31: =+K31+L31 -> 832 | N31: =+M31*P31 -> 832 | O31: =IFERROR(VLOOKUP(E31,'Programa P6 Excel R1'!$A$4:$N$1135,9,FALSE),"-") -> 1 | P31: 1 | Q31: 45775 | R31: =+S31-7 -> 45875 | S31: 45882 | T31: 45895 | U31: 45904 | V31: 45960 | W31: 45796 | X31: 45806 | Y31: 45882 | Z31: 45895 | AC31: 45904 | AD31: 45989
A32: =+TRIM(C32) -> 477-010-40-0023 | B32: 2.2 | C32: 477-010-40-0023 | D32: Rev.P (Aprobado) | E32: 477-PRI24045-001-010-IN-0002 | F32: Brechas de información existente | H32: 1 | K32: 1663 | M32: =+K32+L32 -> 1663 | N32: =+M32*P32 -> 1663 | O32: =IFERROR(VLOOKUP(E32,'Programa P6 Excel R1'!$A$4:$N$1135,9,FALSE),"-") -> 1 | P32: 1 | Q32: 45761 | R32: =+S32-7 -> 45777 | S32: 45784 | T32: 45847 | U32: 45855 | V32: 45861 | W32: 45775 | X32: 45782 | Y32: 45784 | Z32: - | AA32: 45803 | AC32: 45855 | AD32: 45861
A33: =+TRIM(C33) -> 477-010-40-0027 | B33: 2.3 | C33: 477-010-40-0027 | D33: Rev.P (Aprobado) | E33: 477-PRI24045-001-010-IN-0003 | F33: Análisis y verificación propuesta de gestión compromisos ambientales instrumentos anteriores | H33: 1 | K33: 876 | M33: =+K33+L33 -> 876 | N33: =+M33*P33 -> 876 | O33: =IFERROR(VLOOKUP(E33,'Programa P6 Excel R1'!$A$4:$N$1135,9,FALSE),"-") -> 1 | P33: 1 | Q33: 45804 | R33: =+S33-7 -> 45884 | S33: 45891 | T33: 45898 | U33: 45909 | V33: 45960 | W33: 45800 | X33: =+Y33-7 -> 45884 | Y33: 45891 | Z33: 45898 | AC33: 45909 | AD33: 46008
A34: =+TRIM(C34) -> 477-010-40-0031 | B34: 2.4 | C34: 477-010-40-0031 | D34: Rev.P (Aprobado) | E34: 477-PRI24045-001-010-IN-0004 | F34: Identificación preliminar de los Impactos Significativos y estrategia para abordarlos | H34: 1 | K34: 908.5 | M34: =+K34+L34 -> 908.5 | N34: =+M34*P34 -> 908.5 | O34: =IFERROR(VLOOKUP(E34,'Programa P6 Excel R1'!$A$4:$N$1135,9,FALSE),"-") -> 1 | P34: =+'Programa P6 Excel R1'!J87 -> 1 | Q34: 45817 | R34: =+S34-7 -> 45903 | S34: 45910 | T34: 45960 | U34: 45968 | V34: 45975 | W34: 45800 | X34: 45902 | Y34: 45910 | Z34: 45964 | AC34: 45981 | AD34: 46063
B35: 2.5 | F35: Elaboración Capitulos | K35: 0 | M35: =+K35+L35 -> 0 | N35: =+M35*P35 -> 0 | O35: 0 | P35: 0
A36: =+TRIM(C36) -> 477-010-40-0035 | B36: 2.5.1 | C36: 477-010-40-0035 | E36: 477-PRI24045-001-010-IN-0100 | F36: Resumen Ejecutivo | H36: 1 | K36: 196 | M36: =+K36+L36 -> 196 | N36: =+M36*P36 -> 0 | O36: 0 | P36: 0 | Q36: 46317 | R36: =+S36-7 -> 46338 | S36: 46345 | T36: 46352 | U36: 46359 | V36: 46367 | AE36: 46317 | AF36: =+AG36-7 -> 46338 | AG36: 46345 | AH36: 46352 | AI36: 46359 | AJ36: 46367
A37: =+TRIM(C37) -> 477-010-40-0039 | B37: 2.5.2 | C37: 477-010-40-0039 | E37: 477-PRI24045-001-010-IN-0101 | F37: Cap. 1 - Descripción de Proyecto | H37: 1 | K37: 1902 | M37: =+K37+L37 -> 1902 | N37: =+M37*P37 -> 0 | O37: 0 | P37: 0 | Q37: 46216 | R37: =+S37-7 -> 46254 | S37: 46261 | T37: 46268 | U37: 46275 | V37: 46282 | AE37: 46216 | AF37: =+AG37-7 -> 46254 | AG37: 46261 | AH37: 46268 | AI37: 46275 | AJ37: 46282
A38: =+TRIM(C38) -> 477-010-40-0043 | B38: 2.5.3 | C38: 477-010-40-0043 | E38: 477-PRI24045-001-010-IN-0201 | F38: Cap. 2 - Determinación y Justificación Área de Influencia | H38: 1 | K38: 1119.5 | M38: =+K38+L38 -> 1119.5 | N38: =+M38*P38 -> 0 | O38: 0 | P38: 0 | Q38: 46287 | R38: =+S38-7 -> 46322 | S38: 46329 | T38: 46337 | U38: 46345 | V38: 46352 | AE38: 46287 | AF38: =+AG38-7 -> 46322 | AG38: 46329 | AH38: 46337 | AI38: 46345 | AJ38: 46352
A39: =+TRIM(C39) -> 477-010-40-0047 | B39: 2.5.4 | C39: 477-010-40-0047 | E39: 477-PRI24045-001-010-IN-0301 | F39: Cap. 3 - Línea de Base Ambiental | H39: 1 | K39: 314 | M39: =+K39+L39 -> 314 | N39: =+M39*P39 -> 0 | O39: 0 | P39: 0 | Q39: 46287 | R39: =+S39-7 -> 46322 | S39: 46329 | T39: 46342 | U39: 46352 | V39: 46365 | AE39: 46287 | AF39: =+AG39-7 -> 46322 | AG39: 46329 | AH39: 46342 | AI39: 46352 | AJ39: 46365
A40: =+TRIM(C40) -> 477-010-40-0051 | B40: 2.5.5 | C40: 477-010-40-0051 | E40: 477-PRI24045-001-010-IN-0401 | F40: Cap. 4 - Predicción y evaluación de impactos | H40: 1 | K40: 2963 | M40: =+K40+L40 -> 2963 | N40: =+M40*P40 -> 0 | O40: 0 | P40: 0 | Q40: 46287 | R40: =+S40-7 -> 46309 | S40: 46316 | T40: 46329 | U40: 46342 | V40: 46352 | AE40: 46287 | AF40: =+AG40-7 -> 46309 | AG40: 46316 | AH40: 46329 | AI40: 46342 | AJ40: 46352
A41: =+TRIM(C41) -> 477-010-40-0055 | B41: 2.5.6 | C41: 477-010-40-0055 | E41: 477-PRI24045-001-010-IN-0501 | F41: Cap. 5 - Descripción pormenorizada ECC Art.11 | H41: 1 | K41: 331 | M41: =+K41+L41 -> 331 | N41: =+M41*P41 -> 0 | O41: 0 | P41: 0 | Q41: 46287 | R41: =+S41-7 -> 46318 | S41: 46325 | T41: 46336 | U41: 46344 | V41: 46352 | AE41: 46287 | AF41: =+AG41-7 -> 46318 | AG41: 46325 | AH41: 46336 | AI41: 46344 | AJ41: 46352
A42: =+TRIM(C42) -> 477-010-40-0059 | B42: 2.5.7 | C42: 477-010-40-0059 | E42: 477-PRI24045-001-010-IN-0601 | F42: Cap. 6 - Potenciales riesgos para la salud de la población | H42: 1 | K42: 72 | M42: =+K42+L42 -> 72 | N42: =+M42*P42 -> 0 | Q42: 46216 | R42: =+S42-7 -> 46247 | S42: 46254 | T42: 46261 | U42: 46268 | V42: 46275 | AE42: 46216 | AF42: =+AG42-7 -> 46247 | AG42: 46254 | AH42: 46261 | AI42: 46268 | AJ42: 46275
A43: =+TRIM(C43) -> 477-010-40-0063 | B43: 2.5.8 | C43: 477-010-40-0063 | E43: 477-PRI24045-001-010-IN-0701 | F43: Cap. 7 - Plan de medidas de mitigación, reparación y compensación | H43: 1 | K43: 2021 | M43: =+K43+L43 -> 2021 | N43: =+M43*P43 -> 0 | O43: 0 | P43: 0 | Q43: 46287 | R43: =+S43-7 -> 46322 | S43: 46329 | T43: 46337 | U43: 46345 | V43: 46352 | AE43: 46287 | AF43: =+AG43-7 -> 46322 | AG43: 46329 | AH43: 46337 | AI43: 46345 | AJ43: 46352
...

Sheet Curva S R1
D3: CURVA S
D6: 2025 | AP6: 2026 | CQ6: 2027 | EF6: HH | EG6: Fact. | EH6: Avance %
C7: FASE | D7: =+D144 -> 45757 | E7: =+D7+7 -> 45764 | F7: =+E7+7 -> 45771 | G7: =+F7+7 -> 45778 | H7: =+G7+7 -> 45785 | I7: =+H7+7 -> 45792 | J7: =+I7+7 -> 45799 | K7: =+J7+7 -> 45806 | L7: =+K7+7 -> 45813 | ... EC7: =+EB7+7 -> 46660 | EG7: Peso % | EH7: Prog | EI7: Real
EG9: =+#REF!*100 -> #REF! | EH9: =+#REF!/#REF!*100 -> #REF! | EI9: =+#REF!/#REF!*100 -> #REF!
C10: EIA
C11: PROGRAMADO
C12: REAL + FORECAST
EG13: =+#REF!*100 -> #REF! | EH13: =+#REF!/#REF!*100 -> #REF! | EI13: =+#REF!/#REF!*100 -> #REF!
EG17: =+#REF!*100 -> #REF! | EH17: =+#REF!/#REF!*100 -> #REF! | EI17: =+#REF!/#REF!*100 -> #REF!
EG21: =+#REF!*100 -> #REF! | EH21: =+#REF!/#REF!*100 -> #REF! | EI21: =+#REF!/#REF!*100 -> #REF!
EG25: =+#REF!*100 -> #REF! | EH25: =+#REF!/#REF!*100 -> #REF! | EI25: =+#REF!/#REF!*100 -> #REF!
C31: Av. Prog. Parcial (%) - R0 | D31: =+D32 -> 0.22559452 | E31: =+E32-D32 -> 0.48306469 | F31: =+F32-E32 -> 0.37655755 | G31: =+G32-F32 -> 0.44098884 | H31: =+H32-G32 -> 0.47116445 | I31: =+I32-H32 -> 0.7531151 | J31: =+J32-I32 -> 0.59025183 | K31: =+K32-J32 -> 1.1595932 | L31: =+L32-K32 -> 1.3114913 | ... EC31: =+EC32-EB32 -> 0.037145745 | EF31: =SUM(EF13:EF30) -> 0
C32: Av. Prog. Acum. (%) - R0 | D32: =+D46/$EC$46*100 -> 0.22559452 | E32: =+E46/$EC$46*100 -> 0.70865921 | F32: =+F46/$EC$46*100 -> 1.0852168 | G32: =+G46/$EC$46*100 -> 1.5262056 | H32: =+H46/$EC$46*100 -> 1.99737 | I32: =+I46/$EC$46*100 -> 2.7504851 | J32: =+J46/$EC$46*100 -> 3.340737 | K32: =+K46/$EC$46*100 -> 4.5003302 | ... EC32: =+EC46/$EC$46*100 -> 100 | EG32: =SUM(EG8:EG30) -> #REF! | EH32: =SUMPRODUCT(EH8:EH30,EG8:EG30)/100 -> #REF! | EI32: =SUMPRODUCT(EI8:EI30,EG8:EG30)/100 -> #REF!
C33: Av. Prog. Parcial (%) - R1 | D33: =+D34 -> 0.090812451 | E33: =+E34-D34 -> 0.28527388 | F33: =+F34-E34 -> 0.3421692 | G33: =+G34-F34 -> 0.36809739 | H33: =+H34-G34 -> 0.33194781 | I33: =+I34-H34 -> 0.27832143 | J33: =+J34-I34 -> 0.46709013 | K33: =+K34-J34 -> 1.055314 | L33: =+L34-K34 -> 1.1416457 | ... V33: =+V34-U34 -> 1.6474447 | AE33: =+AE34-AD34 -> 0.91640048 | AF33: =+AF34-AE34 -> 1.0328621 | AG33: =+AG34-AF34 -> 1.1231005 | AH33: =+AH34-AG34 -> 1.3977543 | AI33: =+AI34-AH34 -> 2.1524385 | AJ33: =+AJ34-AI34 -> 2.1676031 | AK33: =+AK34-AJ34 -> 1.9202249 | AL33: =+AL34-AK34 -> 1.8739018 | ... EC33: =+EC34-EB34 -> 0.034770246
C34: Av. Prog. Acum. (%) - R1 | D34: =+D56/$EC$56*100 -> 0.090812451 | E34: =+E56/$EC$56*100 -> 0.37608633 | F34: =+F56/$EC$56*100 -> 0.71825553 | G34: =+G56/$EC$56*100 -> 1.0863529 | H34: =+H56/$EC$56*100 -> 1.4183007 | I34: =+I56/$EC$56*100 -> 1.6966222 | J34: =+J56/$EC$56*100 -> 2.1637123 | K34: =+K56/$EC$56*100 -> 3.2190263 | ... W34: =+W56/$EC$56*100 -> 14.099729 | AD34: =+AD56/$EC$56*100 -> 18.486561 | AE34: =+AE56/$EC$56*100 -> 19.402961 | AF34: =+AF56/$EC$56*100 -> 20.435823 | AG34: =+AG56/$EC$56*100 -> 21.558924 | AH34: =+AH56/$EC$56*100 -> 22.956678 | AI34: =+AI56/$EC$56*100 -> 25.109116 | AJ34: =+AJ56/$EC$56*100 -> 27.27672 | AK34: =+AK56/$EC$56*100 -> 29.196944 | ... EC34: =+EC56/$EC$56*100 -> 100
C35: Av. Real + Forecast Parcial (%) | D35: 0.12309012 | E35: 0.24618024 | F35: 0.36927035 | G35: 0.49236047 | H35: 0.47171696 | I35: 1.0185754 | J35: 0.89019735 | K35: 1.0285206 | L35: 0.59118685 | M35: 0.59262338 | N35: 0.95609917 | O35: 0.40681816 | P35: 0.6334327 | Q35: 0.45016903 | R35: 0.36950241 | S35: 1.0622479 | T35: 0.80091314 | U35: 0.84766843 | V35: 0.82778496 | W35: 1.8445411 | X35: 1.4240546 | Y35: 0.72496208 | Z35: 0.90803222 | AA35: 0.36587241 | AB35: 0.19079845 | AC35: 0.27051893 | AD35: 0.48129504 | AE35: 0.5177943 | AF35: 1.0187537 | AG35: 0.99173716 | AH35: 0.95104888 | AI35: 1.650015 | AJ35: 1.8530643 | AK35: 1.6332174 | AL35: 1.8395438 | AM35: 1.1482445 | AN35: 0.4485707 | AO35: 0.33304336 | AP35: 0.31011993 | AQ35: 0.10029641 | AR35: 0.17327757 | AS35: 0.60567924 | AT35: 0.79267804 | AU35: 0.28899616 | AV35: 1.0987849 | AW35: 1.0454379 | AX35: 0.58680157 | AY35: 0.8044234 | AZ35: 0.89620806 | BA35: 0.37586108 | BB35: 0.34793182 | BC35: 0.80994865 | BD35: 0.64970022 | BE35: =+BE36-BD36 -> 0.43510811 | BF35: =+BF36-BE36 -> 0.53640996 | BG35: =+BG36-BF36 -> 1.3576247 | BH35: =+BH36-BG36 -> 2.3236696 | BI35: =+BI36-BH36 -> 2.2091501 | BJ35: =+BJ36-BI36 -> 2.1310125 | BK35: =+BK36-BJ36 -> 1.4184441 | BL35: =+BL36-BK36 -> 2.057395 | ... EC35: =+EC36-EB36 -> 0.033287185
C36: Av. Real + Forecast Acum. (%) | D36: =+D35 -> 0.12309012 | E36: =+D36+E35 -> 0.36927035 | F36: =+E36+F35 -> 0.73854071 | G36: =+F36+G35 -> 1.2309012 | H36: =+G36+H35 -> 1.7026181 | I36: =+H36+I35 -> 2.7211936 | J36: =+I36+J35 -> 3.6113909 | K36: =+J36+K35 -> 4.6399115 | L36: =+K36+L35 -> 5.2310984 | ... BD36: =+BC36+BD35 -> 39.659611 | BE36: =+BE68/125424*100 -> 40.094719 | BF36: =+BF68/$EC$48*100 -> 40.631129 | BG36: =+BG68/$EC$48*100 -> 41.988753 | BH36: =+BH68/$EC$48*100 -> 44.312423 | BI36: =+BI68/$EC$48*100 -> 46.521573 | BJ36: =+BJ68/$EC$48*100 -> 48.652586 | BK36: =+BK68/$EC$48*100 -> 50.07103 | BL36: =+BL68/$EC$48*100 -> 52.128425 | BM36: =+BM68/$EC$48*100 -> 53.576688 | ... EC36: =+EC68/$EC$48*100 -> 100
BE37: =+BE36 -> 40.094719 | BF37: =+BF36 -> 40.631129 | BG37: =+BG36 -> 41.988753 | BH37: =+BH36 -> 44.312423 | BI37: =+BI36 -> 46.521573 | BJ37: =+BJ36 -> 48.652586 | BK37: =+BK36 -> 50.07103 | BL37: =+BL36 -> 52.128425 | ... EC37: =+EC36 -> 100
D41: 0.014765101 | E41: 0.02147651 | F41: 0.042693224 | G41: 0.074529119 | H41: 0.12767915 | I41: 0.21133362 | J41: 0.34310673 | K41: 0.582979 | L41: 0.72684564 | M41: 0.78948907 | N41: 0.86899762 | O41: 0.92297034 | P41: 0.94613553 | Q41: 0.9605398 | R41: 0.97402035 | S41: 0.98268023 | T41: 0.98268023 | U41: 0.99567006
I42: 0.2231 | J42: 0.3392 | K42: 0.50840902 | L42: 0.67858235 | M42: 0.76210709 | N42: 0.79579059 | O42: =+O36/100 -> 0.071866391 | P42: 0.93900679 | Q42: 0.96312026 | R42: 0.96980719 | S42: 0.97649412 | T42: 0.98277579 | U42: 0.99594701
L43: =+L35-L31 -> -0.72030444 | M43: =+M35-M31 -> -0.50041353 | N43: =+N35-N31 -> -0.18164864 | O43: =+O35-O31 -> -0.71375931 | P43: =+P35-P31 -> -0.39644795 | Q43: =+Q35-Q31 -> -0.28679575 | R43: =+R35-R31 -> -0.22091943 | S43: =+S35-S31 -> 0.34270843 | ... X43: =+X35-X31 -> -0.10249103
D45: =+D144 -> 45757 | E45: =+E144 -> 45764 | F45: =+F144 -> 45771 | G45: =+G144 -> 45778 | H45: =+H144 -> 45785 | I45: =+I144 -> 45792 | J45: =+J144 -> 45799 | K45: =+K144 -> 45806 | ... EC45: =+EC144 -> 46660
C46: Av. Prog Base | D46: =+D146 -> 265.4 | E46: =+E146 -> 833.7 | F46: =+F146 -> 1276.7 | G46: =+G146 -> 1795.5 | H46: =+H146 -> 2349.8 | I46: =+I146 -> 3235.8 | J46: =+J146 -> 3930.2 | K46: =+K146 -> 5294.4 | ... EC46: =+EC146 -> 117644.7
C47: Av. Distribución Entregables 4-May
C48: Av. Real/Forecast | D48: =+D152 -> 144.809 | E48: =+E152 -> 434.427 | F48: =+F152 -> 868.854 | G48: =+G152 -> 1448.09 | H48: =+H152 -> 2003.04 | I48: =+I152 -> 3201.34 | J48: =+J152 -> 4248.61 | K48: =+K152 -> 5458.61 | ... AC48: =+AC152 -> 21959.56 | AD48: =+AD62 -> 22798.6 | AE48: =+AE62 -> 23914.57 | AF48: =+AF62 -> 25044.44 | AG48: =+AG62 -> 26234.86 | AH48: =+AH62 -> 27426.86 | AI48: =+AI62 -> 29496.85 | AJ48: =+AJ62 -> 31820.98 | AK48: =+AK62 -> 33869.35 | ... BE48: =+BE62 -> 50288.4 | BF48: =+BF68 -> 53304.64 | BG48: =+BG68 -> 55085.73 | BH48: =+BH68 -> 58134.19 | BI48: =+BI68 -> 61032.41 | BJ48: =+BJ68 -> 63828.12 | BK48: =+BK68 -> 65689 | BL48: =+BL68 -> 68388.13 | BM48: =+BM68 -> 70288.13 | ... EC48: =+EC68 -> 131191.63
B51: PROGRAMA REV.1
B52: Avance Programado
C54: Avance En HH | D54: =+D156 -> 45757 | E54: =+E156 -> 45764 | F54: =+F156 -> 45771 | G54: =+G156 -> 45778 | H54: =+H156 -> 45785 | I54: =+I156 -> 45792 | J54: =+J156 -> 45799 | K54: =+K156 -> 45806 | ... EC54: =+EC156 -> 46660
C55: HH Parcial | D55: =+D75 -> 113.9 | E55: =+E75 -> 357.8 | F55: =+F75 -> 429.16 | G55: =+G75 -> 461.68 | H55: =+H75 -> 416.34 | I55: =+I75 -> 349.08 | J55: =+J75 -> 585.84 | K55: =+K75 -> 1323.61 | ... EC55: =+EC75 -> 43.61
C56: HH Acumuladas | D56: =+D55 -> 113.9 | E56: =+D56+E55 -> 471.7 | F56: =+E56+F55 -> 900.86 | G56: =+F56+G55 -> 1362.54 | H56: =+G56+H55 -> 1778.88 | I56: =+H56+I55 -> 2127.96 | J56: =+I56+J55 -> 2713.8 | K56: =+J56+K55 -> 4037.41 | L56: =+K56+L55 -> 5469.3 | ... EC56: =+EB56+EC55 -> 125423.33
AH57: =+AH55/125423 -> 0.01397758
B58: Avance real | AH58: =+AH56/125423 -> 0.22956738
C60: Avance En HH | D60: =+D54 -> 45757 | E60: =+E54 -> 45764 | F60: =+F54 -> 45771 | G60: =+G54 -> 45778 | H60: =+H54 -> 45785 | I60: =+I54 -> 45792 | J60: =+J54 -> 45799 | K60: =+K54 -> 45806 | ... EC60: =+EC54 -> 46660
C61: HH Parcial | D61: 101.39 | E61: 345.29 | F61: 417.6 | G61: 450.75 | H61: 405.41 | I61: 338.15 | J61: 574.91 | K61: 1312.68 | L61: 1420.96 | M61: 1473.93 | N61: 1457.81 | O61: 473.43 | P61: 404.6 | Q61: 471.77 | R61: 652.14 | S61: 598.86 | T61: 1163.44 | U61: 1204.55 | V61: 2052.35 | W61: 2109.3 | X61: 1334.26 | Y61: 857.42 | Z61: 1145.99 | AA61: 326.65 | AB61: 350.34 | AC61: 500.7 | AD61: 853.92 | AE61: 1115.97 | AF61: 1129.87 | AG61: 1190.42 | AH61: 1192 | AI61: 2069.99 | AJ61: 2324.13 | AK61: 1966.82 | AL61: 2307.3 | AM61: 1440.1 | AN61: 562.63 | AO61: 417.74 | AP61: 264.62 | AQ61: 250.17 | AR61: 217.31 | AS61: 1208 | AT61: 994.2 | AU61: 362.69 | AV61: 1190.97 | AW61: 1086.93 | AX61: 1147.46 | AY61: 1008.94 | AZ61: 1124.06 | BA61: 471.42 | BB61: 471.42 | BC61: 1015.87 | BD61: 814.88 | BE61: =+BE62-BD62 -> 545.73 | BF61: =+BF62-BE62 -> 0 | BG61: =+BG62-BF62 -> 0 | BH61: =+BH62-BG62 -> 0 | BI61: =+BI62-BH62 -> 0 | BJ61: =+BJ62-BI62 -> 0 | BK61: =+BK62-BJ62 -> 0 | BL61: =+BL62-BK62 -> 0 | ... EC61: =+EC62-EB62 -> 0
C62: HH Acumuladas | D62: =+D61 -> 101.39 | E62: =+D62+E61 -> 446.68 | F62: =+E62+F61 -> 864.28 | G62: =+F62+G61 -> 1315.03 | H62: =+G62+H61 -> 1720.44 | I62: =+H62+I61 -> 2058.59 | J62: =+I62+J61 -> 2633.5 | K62: =+J62+K61 -> 3946.18 | L62: =+K62+L61 -> 5367.14 | ... AJ62: =+AI62+AJ61 -> 31820.98 | AK62: 33869.35 | AL62: 36176.65 | AM62: 37616.75 | AN62: 38179.38 | AO62: 38597.12 | AP62: 38861.74 | AQ62: 39111.91 | AR62: 38880.86 | AS62: 40088.86 | AT62: 41083.06 | AU62: 41445.75 | AV62: 42636.72 | AW62: 43723.65 | AX62: 44871.11 | AY62: 45880.05 | AZ62: 47004.11 | BA62: 47475.53 | BB62: 47911.92 | BC62: 48927.79 | BD62: 49742.67 | BE62: =+BE83 -> 50288.4 | BF62: =+BF83 -> 50288.4 | BG62: =+BG83 -> 50288.4 | BH62: =+BH83 -> 50288.4 | BI62: =+BI83 -> 50288.4 | BJ62: =+BJ83 -> 50288.4 | BK62: =+BK83 -> 50288.4 | BL62: =+BL83 -> 50288.4 | ... EC62: =+EC83 -> 50288.4
AH63: =+AH61/125423 -> 0.009503839 | AI63: =+AI61/125423 -> 0.01650407 | AJ63: =+AJ61/125423 -> 0.018530333 | AK63: =+AK61/125423 -> 0.015681494 | AL63: =+AL61/125423 -> 0.018396147 | AM63: =+AM61/125423 -> 0.011481945 | AN63: =+AN61/125423 -> 0.0044858599 | AO63: =+AO61/125423 -> 0.0033306491 | ... BE63: =+BE61/125423 -> 0.0043511158
B64: Forecast | AH64: =+AH62/125423 -> 0.21867488 | AI64: =+AI62/125423 -> 0.23517895 | AJ64: =+AJ62/125423 -> 0.25370929 | AK64: =+AK62/125423 -> 0.27004098 | AL64: =+AL62/125423 -> 0.28843713 | AM64: =+AM62/125423 -> 0.29991907 | AN64: =+AN62/125423 -> 0.30440493 | AO64: =+AO62/125423 -> 0.30773558 | ... BE64: =+BE62/125423 -> 0.40095038
C66: Avance En HH | D66: =+D60 -> 45757 | E66: =+E60 -> 45764 | F66: =+F60 -> 45771 | G66: =+G60 -> 45778 | H66: =+H60 -> 45785 | I66: =+I60 -> 45792 | J66: =+J60 -> 45799 | K66: =+K60 -> 45806 | ... EC66: =+EC60 -> 46660
C67: HH Parcial
C68: HH Acumuladas | BE68: =SUM($D$76:BE76) -> 50288.4 | BF68: =+BE68+BF78 -> 53304.64 | BG68: =+BF68+BG78 -> 55085.73 | BH68: =+BG68+BH78 -> 58134.19 | BI68: =+BH68+BI78 -> 61032.41 | BJ68: =+BI68+BJ78 -> 63828.12 | BK68: =+BJ68+BK78 -> 65689 | BL68: =+BK68+BL78 -> 68388.13 | BM68: =+BL68+BM78 -> 70288.13 | ... EC68: =+EB68+EC78 -> 131191.63
...

Sheet Histog Sem R1
B3: HISTROGRAMA SEMANAL
B58: Semana | C58: 45757 | D58: 45764 | E58: 45771 | F58: 45778 | G58: 45785 | H58: 45792 | I58: 45799 | J58: 45806 | K58: 45813 | L58: 45820 | M58: 45827 | N58: 45834 | O58: 45841 | P58: 45848 | Q58: 45855 | R58: 45862 | S58: 45869 | T58: 45876 | U58: 45883 | V58: 45890 | W58: 45897 | X58: 45904 | Y58: 45911 | Z58: 45918 | AA58: 45925 | AB58: 45932 | AC58: 45939 | AD58: 45946 | AE58: 45953 | AF58: 45960 | AG58: 45967 | AH58: 45974 | AI58: 45981 | AJ58: 45988 | AK58: 45995 | AL58: 46002 | AM58: 46009 | AN58: 46016 | AO58: 46023 | AP58: 46030 | AQ58: 46037 | AR58: 46044 | AS58: 46051 | AT58: 46058 | AU58: 46065 | AV58: 46072 | AW58: 46079 | AX58: 46086 | AY58: 46093 | AZ58: 46100 | BA58: 46107 | BB58: 46114 | BC58: 46121 | BD58: 46128 | BE58: 46135 | BF58: 46142 | BG58: 46149 | BH58: 46156 | BI58: 46163 | BJ58: 46170 | BK58: 46177 | BL58: 46184 | BM58: 46191 | BN58: 46198 | BO58: 46205 | BP58: 46212 | BQ58: 46219 | BR58: 46226 | BS58: 46233 | BT58: 46240 | BU58: 46247 | BV58: 46254 | BW58: 46261 | BX58: 46268 | BY58: 46275 | BZ58: 46282 | CA58: 46289 | CB58: 46296 | CC58: 46303 | CD58: 46310 | CE58: 46317 | CF58: 46324 | CG58: 46331 | CH58: 46338 | CI58: 46345 | CJ58: 46352 | CK58: 46359 | CL58: 46366 | CM58: 46373 | CN58: 46380 | CO58: 46387 | CP58: 46394 | CQ58: 46401 | CR58: 46408 | CS58: 46415 | CT58: 46422 | CU58: 46429 | CV58: 46436 | CW58: 46443 | CX58: 46450 | CY58: 46457 | CZ58: 46464 | DA58: 46471 | DB58: 46478 | DC58: 46485 | DD58: 46492 | DE58: 46499 | DF58: 46506 | DG58: 46513 | DH58: 46520 | DI58: 46527 | DJ58: 46534 | DK58: 46541 | DL58: 46548 | DM58: 46555 | DN58: 46562 | DO58: 46569 | DP58: 46576 | DQ58: 46583 | DR58: 46590 | DS58: 46597 | DT58: 46604 | DU58: 46611 | DV58: 46618 | DW58: 46625 | DX58: 46632 | DY58: 46639 | DZ58: 46646 | EA58: 46653 | EB58: 46660
B59: HH Prog | AD59: =+AD67+AD73 -> 1090.7 | AE59: =+AE67+AE73 -> 1256.93 | AF59: =+AF67+AF73 -> 1371.12 | AG59: =+AG67+AG73 -> 1755.59 | AH59: =+AH67+AH73 -> 2703.42 | AI59: =+AI67+AI73 -> 2723.18 | AJ59: =+AJ67+AJ73 -> 2413.97 | AK59: =+AK67+AK73 -> 2356.32 | ... EB59: =+EB67+EB73 -> 43.6
B60: FTE Parcial | AD60: =+AD68+AD74 -> 19.100964 | AE60: =+AE68+AE74 -> 22.989714 | AF60: =+AF68+AF74 -> 25.265893 | AG60: =+AG68+AG74 -> 30.13625 | AH60: =+AH68+AH74 -> 45.985286 | AI60: =+AI68+AI74 -> 45.464964 | AJ60: =+AJ68+AJ74 -> 41.360429 | AK60: =+AK68+AK74 -> 39.852536 | ... EB60: =+EB68+EB74 -> 1.09
B61: HH Real | C61: 144.809 | D61: 289.618 | E61: 434.427 | F61: 579.236 | G61: 554.95 | H61: 1198.3 | I61: 1047.27 | J61: 1209.97 | K61: 695.5 | L61: 697.19 | M61: 1125.0025 | N61: 495.22754 | O61: 728.5575 | P61: 528.9625 | Q61: 435.0775 | R61: 1497.7725 | S61: 962.71 | T61: 1018.902 | U61: 994.9815 | V61: 2216.9557 | W61: 1711.7525 | X61: 871.4085 | Y61: 1091.4879 | Z61: 439.2095 | AA61: 229.7144 | AB61: 325.0619 | AC61: =1581.93955000003-313 -> 1268.9396 | AD61: =+AD69+AD75 -> 919.7 | AE61: =+AE69+AE75 -> 1101.89 | AF61: =+AF69+AF75 -> 1190.43 | AG61: =+AG69+AG75 -> 1192.45 | AH61: =+AH69+AH75 -> 2069.51 | AI61: =+AI69+AI75 -> 2324.13 | AJ61: =+AJ69+AJ75 -> 2048.37 | AK61: =+AK69+AK75 -> 2307.32 | ... BD61: =+BD69+BD75 -> 1157.94
B62: FTE Parcial Real | C62: 3.620225 | D62: 7.24045 | E62: 10.860675 | F62: 14.4809 | G62: 13.87375 | H62: 29.9575 | I62: 26.18175 | J62: 30.24925 | K62: 17.3875 | L62: 17.42975 | M62: 28.125062 | N62: 12.380689 | O62: 18.213938 | P62: 13.224063 | Q62: 10.876937 | R62: 37.444312 | S62: 24.06775 | T62: 25.47255 | U62: 24.874537 | V62: 55.423891 | W62: 42.793812 | X62: 21.785213 | Y62: 27.287196 | Z62: 10.980237 | AA62: 5.74286 | AB62: 8.1265475 | AC62: 27.98884 | AD62: =+AD70+AD76 -> 17.604286 | AE62: =+AE70+AE76 -> 20.320786 | AF62: =+AF70+AF76 -> 21.451393 | AG62: =+AG70+AG76 -> 21.892964 | AH62: =+AH70+AH76 -> 31.993357 | AI62: =+AI70+AI76 -> 35.938393 | AJ62: =+AJ70+AJ76 -> 32.582786 | AK62: =+AK70+AK76 -> 35.548786 | ... BD62: =+BD70+BD76 -> 23.497071
B66: GABINETE
B67: HH Prog Gabinete | AD67: 328.49 | AE67: 469.8 | AF67: 529.99 | AG67: 471.93 | AH67: 687.4 | AI67: 612.49 | AJ67: 641.68 | AK67: 577.81 | AL67: 378.4 | AM67: 796.72 | AN67: 482.36 | AO67: 430.28 | AP67: 587.74 | AQ67: 533.23 | AR67: 474.42 | AS67: 530.71 | AT67: 495.91 | AU67: 401.11 | AV67: 399.48 | AW67: 751.11 | AX67: 508.42 | AY67: 519.21 | AZ67: 413.89 | BA67: 521.14 | BB67: 690.34 | BC67: 672.87 | BD67: 974.05 | BE67: 1116.95 | BF67: 1422.68 | BG67: 1274.13 | BH67: 1395.98 | BI67: 958.58 | BJ67: 1265.81 | BK67: 1184.97 | BL67: 1072.59 | BM67: 948.62 | BN67: 1128.6 | BO67: 838.97 | BP67: 1180.61 | BQ67: 1626.35 | BR67: 2522.41 | BS67: 2504.32 | BT67: 2309.83 | BU67: 2339.66 | BV67: 2192.81 | BW67: 2714.49 | BX67: 1797.04 | BY67: 1782.39 | BZ67: 1154.39 | CA67: 1050.07 | CB67: 1537.17 | CC67: 1566.49 | CD67: 1118.95 | CE67: 1111.94 | CF67: 808.77 | CG67: 1265.8 | CH67: 1293.82 | CI67: 1300.45 | CJ67: 1178.97 | CK67: 663.01 | CL67: 172.58 | CM67: 543.7 | CN67: 121.52 | CO67: 314.73 | CP67: 125.75 | CQ67: 111.9 | CR67: 80.24 | CS67: 80.24 | CT67: 80.24 | CU67: 80.24 | CV67: 80.24 | CW67: 80.24 | CX67: 200.54 | CY67: 131.44 | CZ67: 110.54 | DA67: 85.94 | DB67: 29.39 | DC67: 36.74 | DD67: 36.74 | DE67: 36.74 | DF67: 36.74 | DG67: 36.74 | DH67: 36.74 | DI67: 36.74 | DJ67: 29.39 | DK67: 36.74 | DL67: 36.74 | DM67: 36.74 | DN67: 29.39 | DO67: 29.39 | DP67: 36.74 | DQ67: 36.74 | DR67: 29.39 | DS67: 36.74 | DT67: 36.74 | DU67: 41.51 | DV67: 48.66 | DW67: 48.66 | DX67: 72.37 | DY67: 72.37 | DZ67: 58.14 | EA67: 38.93 | EB67: 43.6
B68: FTE Parcial Gabinete | AD68: =+AD67/40 -> 8.21225 | AE68: =+AE67/40 -> 11.745 | AF68: =+AF67/40 -> 13.24975 | AG68: =+AG67/40 -> 11.79825 | AH68: =+AH67/40 -> 17.185 | AI68: =+AI67/40 -> 15.31225 | AJ68: =+AJ67/40 -> 16.042 | AK68: =+AK67/40 -> 14.44525 | ... EB68: =+EB67/40 -> 1.09
B69: HH Real | AD69: 416.8 | AE69: 427.42 | AF69: 414.89 | AG69: 453.41 | AH69: 226.7 | AI69: 255.41 | AJ69: 309.9 | AK69: 241.46 | AL69: 199.04 | AM69: 320.47 | AN69: 334 | AO69: 264.61 | AP69: 250.19 | AQ69: 217.32 | AR69: 319.86 | AS69: 337.27 | AT69: 316.75 | AU69: 247.98 | AV69: 288.2 | AW69: 337.74 | AX69: 209.96 | AY69: 330.06 | AZ69: 222.5 | BA69: =+BA92 -> 381.95 | BB69: =+BB92 -> 506.62 | BC69: =+BC92 -> 1158.19 | BD69: =+BD92 -> 649.14 | BE69: =+BE92 -> 0 | BF69: =+BF92 -> 0 | BG69: =+BG92 -> 0 | BH69: =+BH92 -> 0 | ... EB69: =+EB92 -> 0
B70: FTE Parcial Real | AD70: =+AD69/40 -> 10.42 | AE70: =+AE69/40 -> 10.6855 | AF70: =+AF69/40 -> 10.37225 | AG70: =+AG69/40 -> 11.33525 | AH70: =+AH69/40 -> 5.6675 | AI70: =+AI69/40 -> 6.38525 | AJ70: =+AJ69/40 -> 7.7475 | AK70: =+AK69/40 -> 6.0365 | ... EB70: =+EB69/40 -> 0
B72: TERRENO
B73: HH Prog Terreno | AD73: 762.21 | AE73: 787.13 | AF73: 841.13 | AG73: 1283.66 | AH73: 2016.02 | AI73: 2110.69 | AJ73: 1772.29 | AK73: 1778.51 | AL73: 1447.03 | AM73: 262.18 | AN73: 199.71 | AO73: 178.15 | AP73: 331.73 | AQ73: 388.78 | AR73: 548.78 | AS73: 258.81 | AT73: 499.95 | AU73: 678.13 | AV73: 1109.39 | AW73: 1113.17 | AX73: 1061.35 | AY73: 1256.47 | AZ73: 1273.92 | BA73: 559.91 | BB73: 199.95 | BC73: 790.46 | BD73: 1077.61 | BE73: 1490.3 | BF73: 965.19 | BG73: 737.93 | BH73: 802.21 | BI73: 1165.84 | BJ73: 720.12 | BK73: 726.86 | BL73: 766.86 | BM73: 880.84 | BN73: 843.82 | BO73: 722.52 | BP73: 717.28 | BQ73: 595.43 | BR73: 450.43 | BS73: 193.04 | BT73: 0 | BU73: 0 | BV73: 0 | BW73: 0 | BX73: 0 | BY73: 0 | BZ73: 0 | CA73: 0 | CB73: 0 | CC73: 0 | CD73: 0 | CE73: 0 | CF73: 0 | CG73: 0 | CH73: 0 | CI73: 0 | CJ73: 0 | CK73: 0 | CL73: 0 | CM73: 0 | CN73: 0 | CO73: 0 | CP73: 0 | CQ73: 0 | CR73: 0 | CS73: 0 | CT73: 0 | CU73: 0 | CV73: 0 | CW73: 0 | CX73: 0 | CY73: 0 | CZ73: 0 | DA73: 0 | DB73: 0 | DC73: 0 | DD73: 0 | DE73: 0 | DF73: 0 | DG73: 0 | DH73: 0 | DI73: 0 | DJ73: 0 | DK73: 0 | DL73: 0 | DM73: 0 | DN73: 0 | DO73: 0 | DP73: 0 | DQ73: 0 | DR73: 0 | DS73: 0 | DT73: 0 | DU73: 0 | DV73: 0 | DW73: 0 | DX73: 0 | DY73: 0 | DZ73: 0 | EA73: 0 | EB73: 0
B74: FTE Parcial Terreno | AD74: =+AD73/70 -> 10.888714 | AE74: =+AE73/70 -> 11.244714 | AF74: =+AF73/70 -> 12.016143 | AG74: =+AG73/70 -> 18.338 | AH74: =+AH73/70 -> 28.800286 | AI74: =+AI73/70 -> 30.152714 | AJ74: =+AJ73/70 -> 25.318429 | AK74: =+AK73/70 -> 25.407286 | ... EB74: =+EB73/70 -> 0
B75: HH Real | AD75: 502.9 | AE75: 674.47 | AF75: 775.54 | AG75: 739.04 | AH75: 1842.81 | AI75: 2068.72 | AJ75: 1738.47 | AK75: 2065.86 | AL75: 1241.34 | AM75: 241.88 | AN75: 83.74 | AO75: -0.04 | AP75: 0.02 | AQ75: -0.02 | AR75: 967.75 | AS75: 923.78 | AT75: 632.39 | AU75: 1141.4 | AV75: 1157.21 | AW75: 877.01 | AX75: 1170.48 | AY75: 1768.4 | AZ75: 643.17 | BA75: =+BA88 -> 162.31 | BB75: =+BB88 -> 607.92 | BC75: =+BC88 -> 3225.04 | BD75: =+BD88 -> 508.8 | BE75: =+BE88 -> 0 | BF75: =+BF88 -> 0 | BG75: =+BG88 -> 0 | BH75: =+BH88 -> 0 | ... EB75: =+EB88 -> 0
B76: FTE Parcial Real | AD76: =+AD75/70 -> 7.1842857 | AE76: =+AE75/70 -> 9.6352857 | AF76: =+AF75/70 -> 11.079143 | AG76: =+AG75/70 -> 10.557714 | AH76: =+AH75/70 -> 26.325857 | AI76: =+AI75/70 -> 29.553143 | AJ76: =+AJ75/70 -> 24.835286 | AK76: =+AK75/70 -> 29.512286 | ... EB76: =+EB75/70 -> 0
A80: Activity ID | B80: Spreadsheet Field | C80: =+C58 -> 45757 | D80: =+D58 -> 45764 | E80: =+E58 -> 45771 | F80: =+F58 -> 45778 | G80: =+G58 -> 45785 | H80: =+H58 -> 45792 | I80: =+I58 -> 45799 | J80: =+J58 -> 45806 | ... EB80: =+EB58 -> 46660
A81: CMDIC AGP HH Terreno | B81: Actual Labor Units | I81: 246.48 | J81: 1067.89 | K81: 1173.58 | L81: 1173.58 | M81: 1173.58 | N81: 85.89 | R81: 99.56 | S81: 849.95 | T81: 907.59 | U81: 1758.83 | V81: 1858.83 | W81: 957 | X81: 505.97 | Y81: 746.29 | Z81: 117.27 | AA81: 82.04 | AB81: 162.04 | AC81: 552.94 | AD81: 729.14 | AE81: 748.54 | AF81: 775.54
A82: CMDIC AGP HH Terreno | B82: Remaining Labor Units | AG82: 678.58 | AH82: 1955.35 | AI82: 2218.91 | AJ82: 2233.85 | AK82: 1966.72 | AL82: 1408.73 | AM82: 283.16 | AN82: 180.69 | AO82: 148.98 | AP82: 346.04 | AQ82: 388.78 | AR82: 388.78 | AS82: 298.81 | AT82: 559.95 | AU82: 658.13 | AV82: 1285.08 | AW82: 1033.17 | AX82: 1081.35 | AY82: 1209.81 | AZ82: 1260.59 | BA82: 639.91 | BB82: 149.39 | BC82: 783.8 | BD82: 1124.27 | BE82: 1490.3 | BF82: 965.19 | BG82: 788.49 | BH82: 762.21 | BI82: 1165.84 | BJ82: 760.12 | BK82: 726.86 | BL82: 756.86 | BM82: 850.84 | BN82: 843.82 | BO82: 722.52 | BP82: 747.28 | BQ82: 625.43 | BR82: 470.43 | BS82: 193.04
A84: CMDIC AGP HH Oficina | B84: Actual Labor Units | C84: 101.39 | D84: 345.29 | E84: 417.6 | F84: 450.75 | G84: 405.41 | H84: 338.15 | I84: 328.43 | J84: 244.79 | K84: 247.38 | L84: 300.36 | M84: 284.23 | N84: 387.54 | O84: 404.6 | P84: 471.77 | Q84: 652.14 | R84: 499.3 | S84: 313.49 | T84: 296.96 | U84: 293.52 | V84: 250.47 | W84: 377.26 | X84: 351.45 | Y84: 399.69 | Z84: 209.39 | AA84: 268.31 | AB84: 338.66 | AC84: 300.98 | AD84: 386.83 | AE84: 381.34 | AF84: 414.89
A85: CMDIC AGP HH Oficina | B85: Remaining Labor Units | AG85: 367.44 | AH85: 358.29 | AI85: 494.84 | AJ85: 537.18 | AK85: 436.63 | AL85: 340.43 | AM85: 659.02 | AN85: 504.9 | AO85: 493.44 | AP85: 736.04 | AQ85: 703.04 | AR85: 576.49 | AS85: 561.93 | AT85: 649.06 | AU85: 489.11 | AV85: 457.19 | AW85: 819.89 | AX85: 539.3 | AY85: 530.41 | AZ85: 462.13 | BA85: 484.36 | BB85: 748.65 | BC85: 675.56 | BD85: 955.41 | BE85: 1112.97 | BF85: 1513.48 | BG85: 1272.59 | BH85: 1434.09 | BI85: 935.23 | BJ85: 1285.25 | BK85: 1196.74 | BL85: 1109.02 | BM85: 939.55 | BN85: 1111.84 | BO85: 840.16 | BP85: 1178.97 | BQ85: 1606.32 | BR85: 2586.52 | BS85: 2544.44 | BT85: 2359.77 | BU85: 2364.06 | BV85: 2211.69 | BW85: 2722.33 | BX85: 1797.99 | BY85: 1783.33 | BZ85: 1155.33 | CA85: 1050.82 | CB85: 1538.13 | CC85: 1567.54 | CD85: 1119.8 | CE85: 1112.99 | CF85: 809.82 | CG85: 1266.85 | CH85: 1294.88 | CI85: 1301.51 | CJ85: 1180.03 | CK85: 664.07 | CL85: 173.42 | CM85: 544.75 | CN85: 122.57 | CO85: 315.57 | CP85: 125.76 | CQ85: 111.91 | CR85: 80.24 | CS85: 80.24 | CT85: 80.24 | CU85: 80.24 | CV85: 80.24 | CW85: 80.24 | CX85: 200.54 | CY85: 131.44 | CZ85: 110.54 | DA85: 85.94 | DB85: 29.4 | DC85: 36.74 | DD85: 36.74 | DE85: 36.74 | DF85: 36.74 | DG85: 36.74 | DH85: 36.74 | DI85: 36.74 | DJ85: 29.4 | DK85: 36.74 | DL85: 36.74 | DM85: 36.74 | DN85: 29.4 | DO85: 29.4 | DP85: 36.74 | DQ85: 36.74 | DR85: 29.4 | DS85: 36.74 | DT85: 36.74 | DU85: 41.51 | DV85: 48.67 | DW85: 48.67 | DX85: 72.38 | DY85: 72.38 | DZ85: 58.15 | EA85: 38.93 | EB85: 43.61
A88: =+A81 -> CMDIC AGP HH Terreno | I88: 246.48 | J88: 1177.54 | K88: 1329.66 | L88: 1329.66 | M88: 1329.66 | N88: 130.49 | Q88: 138.09 | R88: 348.3 | S88: 1094.21 | T88: 1190.86 | U88: 2100.63 | V88: 2200.63 | W88: 1078.66 | X88: 758.31 | Y88: 1065.42 | Z88: 436.39 | AA88: 260.05 | AB88: 151.91 | AC88: 366.86 | AD88: 394.89 | AE88: 414.29 | AF88: 441.29 | AG88: 703.1 | AH88: 2046.56 | AI88: 2422.56 | AJ88: 1919.16 | AK88: 2019.79 | AL88: 1992.24 | AM88: 1113.31 | AN88: 691.29 | AO88: 367.08 | AP88: 367.08 | AQ88: 367.08 | AR88: 967.75 | AS88: 923.78 | AT88: 632.39 | AU88: 1141.4 | AV88: 1157.21 | AW88: 877.01 | AX88: 1170.48 | AY88: 1768.4 | AZ88: 643.17 | BA88: 162.31 | BB88: 607.92 | BC88: 3225.04 | BD88: =+BD89-BC89 -> 508.8
A89: ACUM | C89: 0 | D89: 0 | E89: 0 | F89: 0 | G89: 0 | H89: 0 | I89: 246.48 | J89: =+I89+J88 -> 1424.02 | K89: =+J89+K88 -> 2753.68 | L89: =+K89+L88 -> 4083.34 | M89: =+L89+M88 -> 5413 | N89: =+M89+N88 -> 5543.49 | O89: =+N89+O88 -> 5543.49 | P89: =+O89+P88 -> 5543.49 | Q89: =+P89+Q88 -> 5681.58 | ... BC89: =+BB89+BC88 -> 45270.39 | BD89: =SUM($C$103:BD103) -> 45779.19
A92: CMDIC AGP HH Oficina | C92: 104.53 | D92: 348.43 | E92: 420.58 | F92: 453.63 | G92: 408.29 | H92: 372.61 | I92: 370.78 | J92: 250.62 | K92: 250.25 | L92: 296.2 | M92: 279.94 | N92: 391.02 | O92: 411.34 | P92: 521.5 | Q92: 678.52 | R92: 517.67 | S92: 331.75 | T92: 310.47 | U92: 303.86 | V92: 258.74 | W92: 392 | X92: 370.17 | Y92: 415.66 | Z92: 219.69 | AA92: 288.8 | AB92: 370.63 | AC92: 334.54 | AD92: 431.8 | AE92: 423.58 | AF92: 420.72 | AG92: 329.41 | AH92: 370.17 | AI92: 336.02 | AJ92: 285.7 | AK92: 272.99 | AL92: 211.4 | AM92: 305.53 | AN92: 285.83 | AO92: 334.86 | AP92: 379.66 | AQ92: 352.33 | AR92: 319.86 | AS92: 337.27 | AT92: 316.75 | AU92: 247.98 | AV92: 288.2 | AW92: 337.74 | AX92: 209.96 | AY92: 330.06 | AZ92: 222.5 | BA92: 381.95 | BB92: 506.62 | BC92: 1158.19 | BD92: =+BD93-BC93 -> 649.14
A93: ACUM | C93: 101.39 | D93: =+C93+D92 -> 449.82 | E93: =+D93+E92 -> 870.4 | F93: =+E93+F92 -> 1324.03 | G93: =+F93+G92 -> 1732.32 | H93: =+G93+H92 -> 2104.93 | I93: =+H93+I92 -> 2475.71 | J93: =+I93+J92 -> 2726.33 | K93: =+J93+K92 -> 2976.58 | ... BC93: =+BB93+BC92 -> 19066.16 | BD93: =SUM($C$105:BD105) -> 19715.3
A95: Total Acum | C95: 101.39 | D95: 446.68 | E95: 864.28 | F95: 1315.03 | G95: 1720.44 | H95: 2058.59 | I95: 2633.5 | J95: 3946.18 | K95: 5367.14 | L95: 6841.08 | M95: 8298.89 | N95: 8772.32 | O95: 9176.92 | P95: 9648.69 | Q95: 10300.83 | R95: 10899.69 | S95: 12063.13 | T95: 13267.68 | U95: 15320.03 | V95: 17429.33 | W95: 18763.59 | X95: 19621.01 | Y95: 20766.99 | Z95: 21093.65 | AA95: 21444 | AB95: 21944.7 | AC95: 22798.62 | AD95: 23914.59 | AE95: 25044.47 | AF95: 26234.9 | AG95: 27427.35 | AH95: 29496.86 | AI95: 31820.99 | AJ95: 33869.36 | AK95: 36176.68 | AL95: 37617.06 | AM95: 38179.41 | AN95: 38597.15 | AO95: 38861.72 | AP95: 39111.93 | AQ95: 39329.23 | AR95: 40088.86 | AS95: 49694.77 | AT95: =+AT89+AT93 -> 49900.41 | AU95: =+AU89+AU93 -> 51289.79 | AV95: =+AV89+AV93 -> 52735.2 | AW95: =+AW89+AW93 -> 53949.95 | AX95: =+AX89+AX93 -> 55330.39 | AY95: =+AY89+AY93 -> 57428.85 | AZ95: =+AZ89+AZ93 -> 58294.52 | BA95: =+BA89+BA93 -> 58838.78 | ... BD95: =+BD89+BD93 -> 65494.49
AX96: =+AX95-AW95 -> 1380.44 | AY96: =+AY95-AX95 -> 2098.46 | AZ96: =+AZ95-AY95 -> 865.67 | BA96: =+BA95-AZ95 -> 544.26 | BB96: =+BB95-BA95 -> 1114.54 | BC96: =+BC95-BB95 -> 4383.23 | BD96: =+BD95-BC95 -> 1157.94
A102: Activity ID | B102: Spreadsheet Field | C102: 45751 | D102: 45758 | E102: 45765 | F102: 45772 | G102: 45779 | H102: 45786 | I102: 45793 | J102: 45800 | K102: 45807 | L102: 45814 | M102: 45821 | N102: 45828 | O102: 45835 | P102: 45842 | Q102: 45849 | R102: 45856 | S102: 45863 | T102: 45870 | U102: 45877 | V102: 45884 | W102: 45891 | X102: 45898 | Y102: 45905 | Z102: 45912 | AA102: 45919 | AB102: 45926 | AC102: 45933 | AD102: 45940 | AE102: 45947 | AF102: 45954 | AG102: 45961 | AH102: 45968 | AI102: 45975 | AJ102: 45982 | AK102: 45989 | AL102: 45996 | AM102: 46003 | AN102: 46010 | AO102: 46017 | AP102: 46024 | AQ102: 46031 | AR102: 46038 | AS102: 46045 | AT102: 46052 | AU102: 46059 | AV102: 46066 | AW102: 46073 | AX102: 46080 | AY102: 46087 | AZ102: 46094 | BA102: 46101 | BB102: 46108 | BC102: 46115 | BD102: 46122 | BE102: 46129 | BF102: 46136 | BG102: 46143 | BH102: 46150 | BI102: 46157 | BJ102: 46164 | BK102: 46171 | BL102: 46178 | BM102: 46185 | BN102: 46192 | BO102: 46199 | BP102: 46206 | BQ102: 46213 | BR102: 46220 | BS102: 46227 | BT102: 46234 | BU102: 46241 | BV102: 46248 | BW102: 46255 | BX102: 46262 | BY102: 46269 | BZ102: 46276 | CA102: 46283 | CB102: 46290 | CC102: 46297 | CD102: 46304 | CE102: 46311 | CF102: 46318 | CG102: 46325 | CH102: 46332 | CI102: 46339 | CJ102: 46346 | CK102: 46353 | CL102: 46360 | CM102: 46367 | CN102: 46374 | CO102: 46381 | CP102: 46388 | CQ102: 46395 | CR102: 46402 | CS102: 46409 | CT102: 46416 | CU102: 46423 | CV102: 46430 | CW102: 46437 | CX102: 46444 | CY102: 46451 | CZ102: 46458 | DA102: 46465 | DB102: 46472 | DC102: 46479 | DD102: 46486 | DE102: 46493 | DF102: 46500 | DG102: 46507 | DH102: 46514 | DI102: 46521 | DJ102: 46528 | DK102: 46535 | DL102: 46542 | DM102: 46549 | DN102: 46556 | DO102: 46563 | DP102: 46570 | DQ102: 46577 | DR102: 46584 | DS102: 46591 | DT102: 46598 | DU102: 46605 | DV102: 46612 | DW102: 46619 | DX102: 46626 | DY102: 46633 | DZ102: 46640 | EA102: 46647 | EB102: 46654 | EC102: 46661 | ED102: 46668 | EE102: 46675 | EF102: 46682 | EG102: 46689 | EH102: 46696 | EI102: 46703 | EJ102: 46710 | EK102: 46717 | EL102: 46724 | EM102: 46731 | EN102: 46738 | EO102: 46745 | EP102: 46752 | EQ102: 46759 | ER102: 46766 | ES102: 46773 | ET102: 46780 | EU102: 46787 | EV102: 46794 | EW102: 46801 | EX102: 46808 | EY102: 46815 | EZ102: 46822 | FA102: 46829 | FB102: 46836 | FC102: 46843
A103: CMDIC AGP HH Terreno | B103: Actual Labor Units | I103: 246.48 | J103: 1177.54 | K103: 1329.66 | L103: 1329.66 | M103: 1329.66 | N103: 130.49 | Q103: 138.09 | R103: 350.09 | S103: 1097.42 | T103: 1194.08 | U103: 2103.84 | V103: 2203.84 | W103: 1081.87 | X103: 761.52 | Y103: 1068.64 | Z103: 439.61 | AA103: 263.27 | AB103: 141.79 | AC103: 337.13 | AD103: 312.85 | AE103: 332.25 | AF103: 359.25 | AG103: 638.27 | AH103: 2027.37 | AI103: 2403.37 | AJ103: 1899.96 | AK103: 2000.6 | AL103: 1981.58 | AM103: 1032.03 | AN103: 610.57 | AO103: 286.37 | AP103: 286.37 | AQ103: 286.37 | AR103: 871.13 | AS103: 890.54 | AT103: 586.27 | AU103: 1216.82 | AV103: 1576.19 | AW103: 1750.28 | AX103: 2084 | AY103: 2193.16 | AZ103: 1267.12 | BA103: 618.02 | BB103: 541.59 | BC103: 264.09 | BD103: 738.09
A105: CMDIC AGP HH Oficina | B105: Actual Labor Units | C105: 103.25 | D105: 347.15 | E105: 419.14 | F105: 452.09 | G105: 406.75 | H105: 371.07 | I105: 369.24 | J105: 249.08 | K105: 248.71 | L105: 292.9 | M105: 276.68 | N105: 387.94 | O105: 408.26 | P105: 518.43 | Q105: 675.45 | R105: 514.72 | S105: 328.83 | T105: 307.39 | U105: 300.66 | V105: 256.18 | W105: 388.8 | X105: 366.97 | Y105: 412.46 | Z105: 217.13 | AA105: 286.23 | AB105: 367.41 | AC105: 331.31 | AD105: 428.82 | AE105: 417.46 | AF105: 412.56 | AG105: 322.17 | AH105: 360.42 | AI105: 327.23 | AJ105: 277.15 | AK105: 264.4 | AL105: 205.66 | AM105: 298.09 | AN105: 285.21 | AO105: 339.11 | AP105: 384.48 | AQ105: 356.73 | AR105: 319.71 | AS105: 338.92 | AT105: 320.45 | AU105: 245.65 | AV105: 224.25 | AW105: 281.78 | AX105: 290.47 | AY105: 300.96 | AZ105: 374.93 | BA105: 520.33 | BB105: 602.56 | BC105: 564.27 | BD105: 1047.3

Sheet Av. Subcontratos
J4: =+'Informe Semanal'!$Q$3 -> 46128
B5: =+'Informe Semanal'!D3 -> Reporte Semanal de Proyectos
B7: =+'Informe Semanal'!G4 -> 477-PRI24045-000-083-RS-0054
B9: Avance de Subcontratos
C11: Subcontrato | D11: Av. Físico Programado | E11: Av. Físico Real | F11: HH Cto. | G11: HH TD | H11: HH Total | I11: HH Plan | J11: HH Ganadas
B12: 1 | C12: GEOBIOTA | D12: =+I12/H12 -> 0.61741904 | E12: =+J12/H12 -> 0.61184763 | F12: 37081 | G12: =3060+1848+7601+2282+359+3272+5260 -> 23682 | H12: =+F12+G12 -> 60763 | I12: 37516.233 | J12: 37177.697
B13: =+B12+1 -> 2 | C13: HIDROESTUDIOS | D13: =+I13/H13 -> 0.084933633 | E13: =+J13/H13 -> 0.073295092 | F13: 7217.4 | H13: =+F13+G13 -> 7217.4 | I13: 613 | J13: 529
B14: =+B13+1 -> 3 | C14: DFM | D14: =+I14/H14 -> 0.012814352 | E14: =+J14/H14 -> 0.012814352 | F14: 2497.2 | H14: =+F14+G14 -> 2497.2 | I14: 32 | J14: 32
B15: =+B14+1 -> 4 | C15: CONTROL ACÚSTICO | D15: =+I15/H15 -> 0.61089303 | E15: =+J15/H15 -> 0.61089303 | F15: 407.6 | H15: =+F15+G15 -> 407.6 | I15: 249 | J15: 249
B16: =+B15+1 -> 5 | C16: PALEOCONSULTORES | D16: =+I16/H16 -> 0.89353612 | E16: =+J16/H16 -> 0.89353612 | F16: 315.6 | H16: =+F16+G16 -> 315.6 | I16: 282 | J16: 282
B17: =+B16+1 -> 6 | C17: ARKA | D17: =+I17/H17 -> 0 | E17: =+J17/H17 -> 0 | F17: 1303.6 | H17: =+F17+G17 -> 1303.6
B18: =+B17+1 -> 7 | C18: COSTA SUR | D18: =+I18/H18 -> 0.47583896 | E18: =+J18/H18 -> 0.4336305 | F18: 10566.6 | H18: =+F18+G18 -> 10566.6 | I18: 5028 | J18: 4582
B19: =+B18+1 -> 8 | C19: AMYT | D19: =+I19/H19 -> 0 | E19: =+J19/H19 -> 0 | F19: 945.2 | H19: =+F19+G19 -> 945.2
B20: =+B19+1 -> 9 | C20: SALIMAX | D20: =+I20/H20 -> 0 | E20: =+J20/H20 -> 0 | F20: 922.209 | H20: =+F20+G20 -> 922.209
B21: =+B20+1 -> 10 | C21: PROAM | D21: =+I21/H21 -> 0 | E21: =+J21/H21 -> 0 | F21: 759 | H21: =+F21+G21 -> 759
B22: =+B21+1 -> 11 | C22: ABOGADO | D22: =+I22/H22 -> 0 | E22: =+J22/H22 -> 0 | F22: 66.8 | H22: =+F22+G22 -> 66.8
B23: =+B22+1 -> 12 | C23: PLATAFORMA DINÁMICA | D23: =+I23/H23 -> 0 | E23: =+J23/H23 -> 0 | F23: 459.2 | H23: =+F23+G23 -> 459.2
B24: =+B23+1 -> 13 | C24: GEOPIXEL | D24: =+I24/H24 -> 0 | E24: =+J24/H24 -> 0 | F24: 75 | H24: =+F24+G24 -> 75
C25: Total | D25: =+I25/F25 -> 0.69822326 | E25: =+J25/F25 -> 0.68435252 | F25: =SUM(F12:F24) -> 62616.409 | G25: =SUM(G12:G24) -> 23682 | H25: =SUM(H12:H24) -> 86298.409 | I25: =SUM(I12:I24) -> 43720.233 | J25: =SUM(J12:J24) -> 42851.697
C27: Nota: Subcontrato Geobiota, se incorpora la Tendencia 12 "Campaña Biótica Complementaria Otoño"

Sheet Log Tendencias
B1: CONTRATO No PRI24045
B2: COMPAÑÍA DOÑA INÉS DE COLLAHUASI
B4: REGISTRO DE TENDENCIAS
B7: Tendencia Tipo : Cambio de Alcance (SC) ; Evolución de Diseño (DE) ; Cambio de Precio (PC) ; Cambio Cantidades (CC) Condiciones de Terreno (ST) ; Transferencias (BT) ; Otro (O) | S7: Fecha de Corte : | T7: =+'Informe Semanal'!Q3 -> 46128
B8: Estado : Potencial (P); Cancelados (C); Pendiente Eval Inicial(PEI);Pendiente Eval Detallada (PED); Emitido GP (EGP);Emitido Cliente (EC); Aprobados (A) ; Rechazado (R )
H10: Impacto | I10: Total | J10: COSTO CLP
B11: Tendencia | C11: OC | D11: Rev. | E11: Título | F11: Tipo | G11: Estado | H11: Ruta | I11: Horas | J11: Costo Directo | K11: Gastos Generales | L11: Utilidades | M11: Viajes y Estadía | N11: Costo Subcontratos | O11: Fee Subcontratos | P11: Descuento Comercial | Q11: GG | R11: Total CLP | S11: Alcance | T11: Observaciones
B12: N° | C12: N° | D12: N° | H12: Crítica
B14: 1 | D14: 0 | E14: Profesionales control operacional de terreno | F14: SC | G14: A | H14: NO | I14: =15+21+516 -> 552 | J14: 573 | K14: C | L14: 46 | M14: 369 | R14: =SUM(J14:Q14) -> 988 | S14: La presente tendencia detalla la incorporación del requerimiento de Collahuasi de tener un representante de WSP durante el desarrollo de las actividades de terreno de subcontratos de WSP, relacionados con el desarrollo de las campañas de líneas de base del EIA ACP Collahuasi, para que actúe de control operacional de terreno y que sea el nexo formal en terreno entre Collahuasi y WSP. | T14: 15/05/25: Versión para revisión 30/05/25: Tendencia fue emitida en Rev.1 04/06/25: Aprobación Collahuasi a Tendencia 1
B15: 2 | D15: C | E15: Profesionales Control Operacional de Terreno (Extensión a Diciembre 25) | F15: SC | G15: A | H15: NO | I15: =84+1920 -> 2004 | J15: 2079 | L15: 166 | R15: =SUM(J15:Q15) -> 2245 | S15: Tendencia que complementa a Tendencia 1. Corresponde a las horas profesionales contempladas para la continuidad del rol de Control Operacional de Terreno, considerando 24 semanas de trabajo (julio 25 a diciembre 25) | T15: Tendencia aprobada.
